Workbook

Sheet Summary
A1: Poornima Institute of Engineering and Technology, Jaipur — Department of Computer Engineering
A2: B.Tech III Semester (CSE & CS(R)) — Attendance Status Report: 75% Eligibility, RTU Debar Risk, Assignments & SODECA Marks
A3: Prepared by: Dr. Anil Kumar, Professor & Head, Department of Computer Engineering. Source: Digital Campus 'Complete Attendance Details' — Sections A, B, C as on 5 Oct 2026; Section D as on 6 Oct 2026 (latest files available with the Department). Student-wise details are on the 'Full Report' tab.
A5: Criteria used (edit the yellow cells — every figure on both tabs recalculates)
A6: RTU minimum attendance for examination eligibility; also the level for full SODECA attendance marks (20/20) | L6: 0.75
A7: Assignments are counted only at or above this attendance (Department rule) | L7: 0.55
A8: RTU debar risk: attendance below this level (threshold used in Department reports, as instructed by HOD) | L8: 0.3
A10: Section-wise status
A11: Section | B11: Data as on | C11: Students | D11: Average Attendance | E11: 75% & above (RTU eligible) | F11: % of Section | G11: Below 75% (RTU shortage) | H11: RTU Debar Risk (<30%) | I11: Assignments Counted (55%+) | J11: Assignments Not Counted (<55%) | K11: Average SODECA (/20) | L11: Full SODECA 20/20
A12: 3CS-A | B12: 46300 | C12: =COUNTIF('Full Report'!$B$6:$B$256,"3CS-A") -> 62 | D12: =AVERAGEIF('Full Report'!$B$6:$B$256,"3CS-A",'Full Report'!$I$6:$I$256) -> 0.70645161 | E12: =COUNTIFS('Full Report'!$B$6:$B$256,"3CS-A",'Full Report'!$I$6:$I$256,">="&Summary!$L$6) -> 39 | F12: =IF(C12=0,"",E12/C12) -> 0.62903226 | G12: =C12-E12 -> 23 | H12: =COUNTIFS('Full Report'!$B$6:$B$256,"3CS-A",'Full Report'!$I$6:$I$256,"<"&Summary!$L$8) -> 5 | I12: =COUNTIFS('Full Report'!$B$6:$B$256,"3CS-A",'Full Report'!$I$6:$I$256,">="&Summary!$L$7) -> 53 | J12: =C12-I12 -> 9 | K12: =AVERAGEIF('Full Report'!$B$6:$B$256,"3CS-A",'Full Report'!$M$6:$M$256) -> 17.593548 | L12: =COUNTIFS('Full Report'!$B$6:$B$256,"3CS-A",'Full Report'!$M$6:$M$256,">=20") -> 39
A13: 3CS-B | B13: 46300 | C13: =COUNTIF('Full Report'!$B$6:$B$256,"3CS-B") -> 63 | D13: =AVERAGEIF('Full Report'!$B$6:$B$256,"3CS-B",'Full Report'!$I$6:$I$256) -> 0.73206349 | E13: =COUNTIFS('Full Report'!$B$6:$B$256,"3CS-B",'Full Report'!$I$6:$I$256,">="&Summary!$L$6) -> 35 | F13: =IF(C13=0,"",E13/C13) -> 0.55555556 | G13: =C13-E13 -> 28 | H13: =COUNTIFS('Full Report'!$B$6:$B$256,"3CS-B",'Full Report'!$I$6:$I$256,"<"&Summary!$L$8) -> 2 | I13: =COUNTIFS('Full Report'!$B$6:$B$256,"3CS-B",'Full Report'!$I$6:$I$256,">="&Summary!$L$7) -> 58 | J13: =C13-I13 -> 5 | K13: =AVERAGEIF('Full Report'!$B$6:$B$256,"3CS-B",'Full Report'!$M$6:$M$256) -> 18.590476 | L13: =COUNTIFS('Full Report'!$B$6:$B$256,"3CS-B",'Full Report'!$M$6:$M$256,">=20") -> 35
A14: 3CS-C | B14: 46300 | C14: =COUNTIF('Full Report'!$B$6:$B$256,"3CS-C") -> 65 | D14: =AVERAGEIF('Full Report'!$B$6:$B$256,"3CS-C",'Full Report'!$I$6:$I$256) -> 0.758 | E14: =COUNTIFS('Full Report'!$B$6:$B$256,"3CS-C",'Full Report'!$I$6:$I$256,">="&Summary!$L$6) -> 44 | F14: =IF(C14=0,"",E14/C14) -> 0.67692308 | G14: =C14-E14 -> 21 | H14: =COUNTIFS('Full Report'!$B$6:$B$256,"3CS-C",'Full Report'!$I$6:$I$256,"<"&Summary!$L$8) -> 2 | I14: =COUNTIFS('Full Report'!$B$6:$B$256,"3CS-C",'Full Report'!$I$6:$I$256,">="&Summary!$L$7) -> 61 | J14: =C14-I14 -> 4 | K14: =AVERAGEIF('Full Report'!$B$6:$B$256,"3CS-C",'Full Report'!$M$6:$M$256) -> 18.818462 | L14: =COUNTIFS('Full Report'!$B$6:$B$256,"3CS-C",'Full Report'!$M$6:$M$256,">=20") -> 44
A15: 3CSR-D | B15: 46301 | C15: =COUNTIF('Full Report'!$B$6:$B$256,"3CSR-D") -> 61 | D15: =AVERAGEIF('Full Report'!$B$6:$B$256,"3CSR-D",'Full Report'!$I$6:$I$256) -> 0.74278689 | E15: =COUNTIFS('Full Report'!$B$6:$B$256,"3CSR-D",'Full Report'!$I$6:$I$256,">="&Summary!$L$6) -> 37 | F15: =IF(C15=0,"",E15/C15) -> 0.60655738 | G15: =C15-E15 -> 24 | H15: =COUNTIFS('Full Report'!$B$6:$B$256,"3CSR-D",'Full Report'!$I$6:$I$256,"<"&Summary!$L$8) -> 1 | I15: =COUNTIFS('Full Report'!$B$6:$B$256,"3CSR-D",'Full Report'!$I$6:$I$256,">="&Summary!$L$7) -> 56 | J15: =C15-I15 -> 5 | K15: =AVERAGEIF('Full Report'!$B$6:$B$256,"3CSR-D",'Full Report'!$M$6:$M$256) -> 18.744262 | L15: =COUNTIFS('Full Report'!$B$6:$B$256,"3CSR-D",'Full Report'!$M$6:$M$256,">=20") -> 37
A16: Total (III Sem) | C16: =SUM(C12:C15) -> 251 | D16: =AVERAGE('Full Report'!$I$6:$I$256) -> 0.73505976 | E16: =SUM(E12:E15) -> 155 | F16: =IF(C16=0,"",E16/C16) -> 0.61752988 | G16: =SUM(G12:G15) -> 96 | H16: =SUM(H12:H15) -> 10 | I16: =SUM(I12:I15) -> 228 | J16: =SUM(J12:J15) -> 23 | K16: =AVERAGE('Full Report'!$M$6:$M$256) -> 18.440637 | L16: =SUM(L12:L15) -> 155
A18: Attendance distribution (number of students)
A19: Category | B19: What it means | E19: 3CS-A | F19: 3CS-B | G19: 3CS-C | H19: 3CSR-D | I19: Total
A20: 75%+ (all benefits) | B20: RTU eligible · full SODECA 20/20 · assignments counted | E20: =COUNTIFS('Full Report'!$B$6:$B$256,"3CS-A",'Full Report'!$O$6:$O$256,"75%+ (all benefits)") -> 39 | F20: =COUNTIFS('Full Report'!$B$6:$B$256,"3CS-B",'Full Report'!$O$6:$O$256,"75%+ (all benefits)") -> 35 | G20: =COUNTIFS('Full Report'!$B$6:$B$256,"3CS-C",'Full Report'!$O$6:$O$256,"75%+ (all benefits)") -> 44 | H20: =COUNTIFS('Full Report'!$B$6:$B$256,"3CSR-D",'Full Report'!$O$6:$O$256,"75%+ (all benefits)") -> 37 | I20: =SUM(E20:H20) -> 155
A21: 55–74% | B21: RTU shortage · SODECA reduced · assignments counted | E21: =COUNTIFS('Full Report'!$B$6:$B$256,"3CS-A",'Full Report'!$O$6:$O$256,"55–74%") -> 14 | F21: =COUNTIFS('Full Report'!$B$6:$B$256,"3CS-B",'Full Report'!$O$6:$O$256,"55–74%") -> 23 | G21: =COUNTIFS('Full Report'!$B$6:$B$256,"3CS-C",'Full Report'!$O$6:$O$256,"55–74%") -> 17 | H21: =COUNTIFS('Full Report'!$B$6:$B$256,"3CSR-D",'Full Report'!$O$6:$O$256,"55–74%") -> 19 | I21: =SUM(E21:H21) -> 73
A22: 30–54% | B22: RTU shortage · SODECA reduced · assignments NOT counted | E22: =COUNTIFS('Full Report'!$B$6:$B$256,"3CS-A",'Full Report'!$O$6:$O$256,"30–54%") -> 4 | F22: =COUNTIFS('Full Report'!$B$6:$B$256,"3CS-B",'Full Report'!$O$6:$O$256,"30–54%") -> 3 | G22: =COUNTIFS('Full Report'!$B$6:$B$256,"3CS-C",'Full Report'!$O$6:$O$256,"30–54%") -> 2 | H22: =COUNTIFS('Full Report'!$B$6:$B$256,"3CSR-D",'Full Report'!$O$6:$O$256,"30–54%") -> 4 | I22: =SUM(E22:H22) -> 13
A23: Below 30% | B23: RTU debar risk · assignments NOT counted | E23: =COUNTIFS('Full Report'!$B$6:$B$256,"3CS-A",'Full Report'!$O$6:$O$256,"Below 30%") -> 5 | F23: =COUNTIFS('Full Report'!$B$6:$B$256,"3CS-B",'Full Report'!$O$6:$O$256,"Below 30%") -> 2 | G23: =COUNTIFS('Full Report'!$B$6:$B$256,"3CS-C",'Full Report'!$O$6:$O$256,"Below 30%") -> 2 | H23: =COUNTIFS('Full Report'!$B$6:$B$256,"3CSR-D",'Full Report'!$O$6:$O$256,"Below 30%") -> 1 | I23: =SUM(E23:H23) -> 10
A24: Total | E24: =SUM(E20:E23) -> 62 | F24: =SUM(F20:F23) -> 63 | G24: =SUM(G20:G23) -> 65 | H24: =SUM(H20:H23) -> 61 | I24: =SUM(I20:I23) -> 251
A26: Students at RTU debar risk (attendance below 30%) — immediate attention required
A27: S.No | B27: Section | C27: Reg. No | D27: Name | G27: Present | H27: Total | I27: Attendance % | J27: SODECA (/20) | K27: Assignments
A28: 1 | B28: 3CS-A | C28: PIET25CS033 | D28: ATHARAV AGARWAL | G28: ='Full Report'!F36 -> 1 | H28: ='Full Report'!H36 -> 102 | I28: ='Full Report'!I36 -> 0.01 | J28: ='Full Report'!M36 -> 0.2 | K28: ='Full Report'!L36 -> Not Counted
A29: 2 | B29: 3CS-A | C29: PIET25CS057 | D29: HARSH KUMAR | G29: ='Full Report'!F60 -> 43 | H29: ='Full Report'!H60 -> 366 | I29: ='Full Report'!I60 -> 0.12 | J29: ='Full Report'!M60 -> 3.2 | K29: ='Full Report'!L60 -> Not Counted
A30: 3 | B30: 3CS-A | C30: PIET25CS034 | D30: AYUSH JANGIR | G30: ='Full Report'!F37 -> 52 | H30: ='Full Report'!H37 -> 366 | I30: ='Full Report'!I37 -> 0.14 | J30: ='Full Report'!M37 -> 3.8 | K30: ='Full Report'!L37 -> Not Counted
A31: 4 | B31: 3CS-A | C31: PIET25CS044 | D31: DEVANSH SONI | G31: ='Full Report'!F47 -> 53 | H31: ='Full Report'!H47 -> 366 | I31: ='Full Report'!I47 -> 0.14 | J31: ='Full Report'!M47 -> 3.8 | K31: ='Full Report'!L47 -> Not Counted
A32: 5 | B32: 3CS-A | C32: PIET25CS031 | D32: ARYAN KUMAR | G32: ='Full Report'!F35 -> 76 | H32: ='Full Report'!H35 -> 366 | I32: ='Full Report'!I35 -> 0.21 | J32: ='Full Report'!M35 -> 5.6 | K32: ='Full Report'!L35 -> Not Counted
A33: 6 | B33: 3CS-B | C33: PIET25CS098 | D33: NAITIK BHATI | G33: ='Full Report'!F100 -> 56 | H33: ='Full Report'!H100 -> 366 | I33: ='Full Report'!I100 -> 0.15 | J33: ='Full Report'!M100 -> 4 | K33: ='Full Report'!L100 -> Not Counted
A34: 7 | B34: 3CS-B | C34: PIET25CS076 | D34: KHILVANSH SHARMA | G34: ='Full Report'!F78 -> 84 | H34: ='Full Report'!H78 -> 366 | I34: ='Full Report'!I78 -> 0.23 | J34: ='Full Report'!M78 -> 6.2 | K34: ='Full Report'!L78 -> Not Counted
A35: 8 | B35: 3CS-C | C35: PIET25CS192 | D35: SHUBHAM PRAJAPAT | G35: ='Full Report'!F193 -> 19 | H35: ='Full Report'!H193 -> 366 | I35: ='Full Report'!I193 -> 0.05 | J35: ='Full Report'!M193 -> 1.4 | K35: ='Full Report'!L193 -> Not Counted
A36: 9 | B36: 3CS-C | C36: PIET25CS190 | D36: RISHABH JAIN | G36: ='Full Report'!F192 -> 26 | H36: ='Full Report'!H192 -> 366 | I36: ='Full Report'!I192 -> 0.07 | J36: ='Full Report'!M192 -> 1.8 | K36: ='Full Report'!L192 -> Not Counted
A37: 10 | B37: 3CSR-D | C37: PIET25CR050 | D37: SAKSHAM NAGAR | G37: ='Full Report'!F241 -> 62 | H37: ='Full Report'!H241 -> 372 | I37: ='Full Report'!I241 -> 0.17 | J37: ='Full Report'!M241 -> 4.6 | K37: ='Full Report'!L241 -> Not Counted
A39: Notes
A40: • RTU eligibility: 75% attendance is required for examination eligibility; students below 30% are flagged as at risk of debarment.
A41: • Assignments are counted only for students with 55% or more attendance (Department rule). For the student-wise list, filter 'Assignments' on the Full Report tab.
A42: • SODECA attendance component = 20 marks (Theory 10 + Practical 10): full marks at 75%+, proportional below 75% (SODECA scheme, II Year). Theory and Practical are taken at the same overall % here.
A43: • Sections A, B and C are as on 5 Oct 2026; Section D is as on 6 Oct 2026. Share the latest A/B/C file to bring all sections to the same date.

Sheet Full Report
A1: Department of Computer Engineering, PIET Jaipur
A2: B.Tech III Semester — Student-wise Attendance Status (Sections A, B, C & D)
A3: Attendance % = Present ÷ Total periods, rounded to a whole % as displayed in Digital Campus. SODECA attendance marks: 20/20 at 75%+, otherwise proportional (attendance ÷ 75% × 10 for Theory and for Practical). Filter 'Assignments' = Not Counted for the assignments list, or 'RTU Debar Risk' = YES for the debar-risk list. Criteria are on the Summary tab.
A5: S.No | B5: Section | C5: Reg. No | D5: Name | E5: Data as on | F5: Present | G5: Absent | H5: Total Periods | I5: Attendance % | J5: RTU 75% Eligibility | K5: RTU Debar Risk (<30%) | L5: Assignments (55%+) | M5: SODECA Attendance Marks (/20) | N5: SODECA Marks Lost | O5: Overall Category
A6: 1 | B6: 3CS-A | C6: PIET25CS001 | D6: AABHAS GHIYA | E6: 46300 | F6: 287 | G6: 79 | H6: 366 | I6: =ROUND(F6/H6*100,0)/100 -> 0.78 | J6: =IF(I6>=Summary!$L$6,"Eligible","Shortage") -> Eligible | K6: =IF(I6<Summary!$L$8,"YES","No") -> No | L6: =IF(I6>=Summary!$L$7,"Counted","Not Counted") -> Counted | M6: =IF(I6>=Summary!$L$6,20,ROUND(I6/Summary!$L$6*10,1)*2) -> 20 | N6: =20-M6 -> 0 | O6: =IF(I6>=Summary!$L$6,"75%+ (all benefits)",IF(I6>=Summary!$L$7,"55–74%",IF(I6>=Summary!$L$8,"30–54%","Below 30%"))) -> 75%+ (all benefits)
A7: 2 | B7: 3CS-A | C7: PIET25CS002 | D7: AARJAV JAIN | E7: 46300 | F7: 282 | G7: 84 | H7: 366 | I7: =ROUND(F7/H7*100,0)/100 -> 0.77 | J7: =IF(I7>=Summary!$L$6,"Eligible","Shortage") -> Eligible | K7: =IF(I7<Summary!$L$8,"YES","No") -> No | L7: =IF(I7>=Summary!$L$7,"Counted","Not Counted") -> Counted | M7: =IF(I7>=Summary!$L$6,20,ROUND(I7/Summary!$L$6*10,1)*2) -> 20 | N7: =20-M7 -> 0 | O7: =IF(I7>=Summary!$L$6,"75%+ (all benefits)",IF(I7>=Summary!$L$7,"55–74%",IF(I7>=Summary!$L$8,"30–54%","Below 30%"))) -> 75%+ (all benefits)
A8: 3 | B8: 3CS-A | C8: PIET25CS003 | D8: AARYA MAHESHWARI | E8: 46300 | F8: 253 | G8: 113 | H8: 366 | I8: =ROUND(F8/H8*100,0)/100 -> 0.69 | J8: =IF(I8>=Summary!$L$6,"Eligible","Shortage") -> Shortage | K8: =IF(I8<Summary!$L$8,"YES","No") -> No | L8: =IF(I8>=Summary!$L$7,"Counted","Not Counted") -> Counted | M8: =IF(I8>=Summary!$L$6,20,ROUND(I8/Summary!$L$6*10,1)*2) -> 18.4 | N8: =20-M8 -> 1.6 | O8: =IF(I8>=Summary!$L$6,"75%+ (all benefits)",IF(I8>=Summary!$L$7,"55–74%",IF(I8>=Summary!$L$8,"30–54%","Below 30%"))) -> 55–74%
A9: 4 | B9: 3CS-A | C9: PIET25CS004 | D9: AASID KHAN | E9: 46300 | F9: 297 | G9: 69 | H9: 366 | I9: =ROUND(F9/H9*100,0)/100 -> 0.81 | J9: =IF(I9>=Summary!$L$6,"Eligible","Shortage") -> Eligible | K9: =IF(I9<Summary!$L$8,"YES","No") -> No | L9: =IF(I9>=Summary!$L$7,"Counted","Not Counted") -> Counted | M9: =IF(I9>=Summary!$L$6,20,ROUND(I9/Summary!$L$6*10,1)*2) -> 20 | N9: =20-M9 -> 0 | O9: =IF(I9>=Summary!$L$6,"75%+ (all benefits)",IF(I9>=Summary!$L$7,"55–74%",IF(I9>=Summary!$L$8,"30–54%","Below 30%"))) -> 75%+ (all benefits)
A10: 5 | B10: 3CS-A | C10: PIET25CS005 | D10: ABHINAV MATHUR | E10: 46300 | F10: 295 | G10: 71 | H10: 366 | I10: =ROUND(F10/H10*100,0)/100 -> 0.81 | J10: =IF(I10>=Summary!$L$6,"Eligible","Shortage") -> Eligible | K10: =IF(I10<Summary!$L$8,"YES","No") -> No | L10: =IF(I10>=Summary!$L$7,"Counted","Not Counted") -> Counted | M10: =IF(I10>=Summary!$L$6,20,ROUND(I10/Summary!$L$6*10,1)*2) -> 20 | N10: =20-M10 -> 0 | O10: =IF(I10>=Summary!$L$6,"75%+ (all benefits)",IF(I10>=Summary!$L$7,"55–74%",IF(I10>=Summary!$L$8,"30–54%","Below 30%"))) -> 75%+ (all benefits)
A11: 6 | B11: 3CS-A | C11: PIET25CS006 | D11: ABHINAV SHARMA | E11: 46300 | F11: 305 | G11: 61 | H11: 366 | I11: =ROUND(F11/H11*100,0)/100 -> 0.83 | J11: =IF(I11>=Summary!$L$6,"Eligible","Shortage") -> Eligible | K11: =IF(I11<Summary!$L$8,"YES","No") -> No | L11: =IF(I11>=Summary!$L$7,"Counted","Not Counted") -> Counted | M11: =IF(I11>=Summary!$L$6,20,ROUND(I11/Summary!$L$6*10,1)*2) -> 20 | N11: =20-M11 -> 0 | O11: =IF(I11>=Summary!$L$6,"75%+ (all benefits)",IF(I11>=Summary!$L$7,"55–74%",IF(I11>=Summary!$L$8,"30–54%","Below 30%"))) -> 75%+ (all benefits)
A12: 7 | B12: 3CS-A | C12: PIET25CS007 | D12: ABHISHEK SHARMA | E12: 46300 | F12: 293 | G12: 73 | H12: 366 | I12: =ROUND(F12/H12*100,0)/100 -> 0.8 | J12: =IF(I12>=Summary!$L$6,"Eligible","Shortage") -> Eligible | K12: =IF(I12<Summary!$L$8,"YES","No") -> No | L12: =IF(I12>=Summary!$L$7,"Counted","Not Counted") -> Counted | M12: =IF(I12>=Summary!$L$6,20,ROUND(I12/Summary!$L$6*10,1)*2) -> 20 | N12: =20-M12 -> 0 | O12: =IF(I12>=Summary!$L$6,"75%+ (all benefits)",IF(I12>=Summary!$L$7,"55–74%",IF(I12>=Summary!$L$8,"30–54%","Below 30%"))) -> 75%+ (all benefits)
A13: 8 | B13: 3CS-A | C13: PIET25CS008 | D13: ADITI MALAV | E13: 46300 | F13: 284 | G13: 82 | H13: 366 | I13: =ROUND(F13/H13*100,0)/100 -> 0.78 | J13: =IF(I13>=Summary!$L$6,"Eligible","Shortage") -> Eligible | K13: =IF(I13<Summary!$L$8,"YES","No") -> No | L13: =IF(I13>=Summary!$L$7,"Counted","Not Counted") -> Counted | M13: =IF(I13>=Summary!$L$6,20,ROUND(I13/Summary!$L$6*10,1)*2) -> 20 | N13: =20-M13 -> 0 | O13: =IF(I13>=Summary!$L$6,"75%+ (all benefits)",IF(I13>=Summary!$L$7,"55–74%",IF(I13>=Summary!$L$8,"30–54%","Below 30%"))) -> 75%+ (all benefits)
A14: 9 | B14: 3CS-A | C14: PIET25CS009 | D14: ADITYA AGARWAL | E14: 46300 | F14: 254 | G14: 112 | H14: 366 | I14: =ROUND(F14/H14*100,0)/100 -> 0.69 | J14: =IF(I14>=Summary!$L$6,"Eligible","Shortage") -> Shortage | K14: =IF(I14<Summary!$L$8,"YES","No") -> No | L14: =IF(I14>=Summary!$L$7,"Counted","Not Counted") -> Counted | M14: =IF(I14>=Summary!$L$6,20,ROUND(I14/Summary!$L$6*10,1)*2) -> 18.4 | N14: =20-M14 -> 1.6 | O14: =IF(I14>=Summary!$L$6,"75%+ (all benefits)",IF(I14>=Summary!$L$7,"55–74%",IF(I14>=Summary!$L$8,"30–54%","Below 30%"))) -> 55–74%
A15: 10 | B15: 3CS-A | C15: PIET25CS010 | D15: ADITYA KUMAR JAIN | E15: 46300 | F15: 302 | G15: 64 | H15: 366 | I15: =ROUND(F15/H15*100,0)/100 -> 0.83 | J15: =IF(I15>=Summary!$L$6,"Eligible","Shortage") -> Eligible | K15: =IF(I15<Summary!$L$8,"YES","No") -> No | L15: =IF(I15>=Summary!$L$7,"Counted","Not Counted") -> Counted | M15: =IF(I15>=Summary!$L$6,20,ROUND(I15/Summary!$L$6*10,1)*2) -> 20 | N15: =20-M15 -> 0 | O15: =IF(I15>=Summary!$L$6,"75%+ (all benefits)",IF(I15>=Summary!$L$7,"55–74%",IF(I15>=Summary!$L$8,"30–54%","Below 30%"))) -> 75%+ (all benefits)
A16: 11 | B16: 3CS-A | C16: PIET25CS012 | D16: AJAY CHOUDHARY | E16: 46300 | F16: 279 | G16: 87 | H16: 366 | I16: =ROUND(F16/H16*100,0)/100 -> 0.76 | J16: =IF(I16>=Summary!$L$6,"Eligible","Shortage") -> Eligible | K16: =IF(I16<Summary!$L$8,"YES","No") -> No | L16: =IF(I16>=Summary!$L$7,"Counted","Not Counted") -> Counted | M16: =IF(I16>=Summary!$L$6,20,ROUND(I16/Summary!$L$6*10,1)*2) -> 20 | N16: =20-M16 -> 0 | O16: =IF(I16>=Summary!$L$6,"75%+ (all benefits)",IF(I16>=Summary!$L$7,"55–74%",IF(I16>=Summary!$L$8,"30–54%","Below 30%"))) -> 75%+ (all benefits)
A17: 12 | B17: 3CS-A | C17: PIET25CS013 | D17: AKHILESH AGNIHOTRI | E17: 46300 | F17: 184 | G17: 182 | H17: 366 | I17: =ROUND(F17/H17*100,0)/100 -> 0.5 | J17: =IF(I17>=Summary!$L$6,"Eligible","Shortage") -> Shortage | K17: =IF(I17<Summary!$L$8,"YES","No") -> No | L17: =IF(I17>=Summary!$L$7,"Counted","Not Counted") -> Not Counted | M17: =IF(I17>=Summary!$L$6,20,ROUND(I17/Summary!$L$6*10,1)*2) -> 13.4 | N17: =20-M17 -> 6.6 | O17: =IF(I17>=Summary!$L$6,"75%+ (all benefits)",IF(I17>=Summary!$L$7,"55–74%",IF(I17>=Summary!$L$8,"30–54%","Below 30%"))) -> 30–54%
... A101: 96 | B101: 3CS-B | C101: PIET25CS099 | D101: NAMAN GUPTA | E101: 46300 | F101: 302 | G101: 64 | H101: 366 | I101: =ROUND(F101/H101*100,0)/100 -> 0.83 | J101: =IF(I101>=Summary!$L$6,"Eligible","Shortage") -> Eligible | K101: =IF(I101<Summary!$L$8,"YES","No") -> No | L101: =IF(I101>=Summary!$L$7,"Counted","Not Counted") -> Counted | M101: =IF(I101>=Summary!$L$6,20,ROUND(I101/Summary!$L$6*10,1)*2) -> 20 | N101: =20-M101 -> 0 | O101: =IF(I101>=Summary!$L$6,"75%+ (all benefits)",IF(I101>=Summary!$L$7,"55–74%",IF(I101>=Summary!$L$8,"30–54%","Below 30%"))) -> 75%+ (all benefits)
A102: 97 | B102: 3CS-B | C102: PIET25CS100 | E102: 46300 | F102: 296 | G102: 79 | H102: 375 | I102: =ROUND(F102/H102*100,0)/100 -> 0.79 | J102: =IF(I102>=Summary!$L$6,"Eligible","Shortage") -> Eligible | K102: =IF(I102<Summary!$L$8,"YES","No") -> No | L102: =IF(I102>=Summary!$L$7,"Counted","Not Counted") -> Counted | M102: =IF(I102>=Summary!$L$6,20,ROUND(I102/Summary!$L$6*10,1)*2) -> 20 | N102: =20-M102 -> 0 | O102: =IF(I102>=Summary!$L$6,"75%+ (all benefits)",IF(I102>=Summary!$L$7,"55–74%",IF(I102>=Summary!$L$8,"30–54%","Below 30%"))) -> 75%+ (all benefits)
A103: 98 | B103: 3CS-B | C103: PIET25CS101 | D103: NAVYA SHARMA | E103: 46300 | F103: 254 | G103: 112 | H103: 366 | I103: =ROUND(F103/H103*100,0)/100 -> 0.69 | J103: =IF(I103>=Summary!$L$6,"Eligible","Shortage") -> Shortage | K103: =IF(I103<Summary!$L$8,"YES","No") -> No | L103: =IF(I103>=Summary!$L$7,"Counted","Not Counted") -> Counted | M103: =IF(I103>=Summary!$L$6,20,ROUND(I103/Summary!$L$6*10,1)*2) -> 18.4 | N103: =20-M103 -> 1.6 | O103: =IF(I103>=Summary!$L$6,"75%+ (all benefits)",IF(I103>=Summary!$L$7,"55–74%",IF(I103>=Summary!$L$8,"30–54%","Below 30%"))) -> 55–74%
A104: 99 | B104: 3CS-B | C104: PIET25CS102 | D104: MS. NEELAM JAIN | E104: 46300 | F104: 296 | G104: 70 | H104: 366 | I104: =ROUND(F104/H104*100,0)/100 -> 0.81 | J104: =IF(I104>=Summary!$L$6,"Eligible","Shortage") -> Eligible | K104: =IF(I104<Summary!$L$8,"YES","No") -> No | L104: =IF(I104>=Summary!$L$7,"Counted","Not Counted") -> Counted | M104: =IF(I104>=Summary!$L$6,20,ROUND(I104/Summary!$L$6*10,1)*2) -> 20 | N104: =20-M104 -> 0 | O104: =IF(I104>=Summary!$L$6,"75%+ (all benefits)",IF(I104>=Summary!$L$7,"55–74%",IF(I104>=Summary!$L$8,"30–54%","Below 30%"))) -> 75%+ (all benefits)
A105: 100 | B105: 3CS-B | C105: PIET25CS103 | D105: NEERAJ DULANI | E105: 46300 | F105: 259 | G105: 107 | H105: 366 | I105: =ROUND(F105/H105*100,0)/100 -> 0.71 | J105: =IF(I105>=Summary!$L$6,"Eligible","Shortage") -> Shortage | K105: =IF(I105<Summary!$L$8,"YES","No") -> No | L105: =IF(I105>=Summary!$L$7,"Counted","Not Counted") -> Counted | M105: =IF(I105>=Summary!$L$6,20,ROUND(I105/Summary!$L$6*10,1)*2) -> 19 | N105: =20-M105 -> 1 | O105: =IF(I105>=Summary!$L$6,"75%+ (all benefits)",IF(I105>=Summary!$L$7,"55–74%",IF(I105>=Summary!$L$8,"30–54%","Below 30%"))) -> 55–74%
A106: 101 | B106: 3CS-B | C106: PIET25CS104 | D106: NIKHIL KUMAR | E106: 46300 | F106: 226 | G106: 140 | H106: 366 | I106: =ROUND(F106/H106*100,0)/100 -> 0.62 | J106: =IF(I106>=Summary!$L$6,"Eligible","Shortage") -> Shortage | K106: =IF(I106<Summary!$L$8,"YES","No") -> No | L106: =IF(I106>=Summary!$L$7,"Counted","Not Counted") -> Counted | M106: =IF(I106>=Summary!$L$6,20,ROUND(I106/Summary!$L$6*10,1)*2) -> 16.6 | N106: =20-M106 -> 3.4 | O106: =IF(I106>=Summary!$L$6,"75%+ (all benefits)",IF(I106>=Summary!$L$7,"55–74%",IF(I106>=Summary!$L$8,"30–54%","Below 30%"))) -> 55–74%
A107: 102 | B107: 3CS-B | C107: PIET25CS105 | D107: NIKHIL SHARMA | E107: 46300 | F107: 266 | G107: 100 | H107: 366 | I107: =ROUND(F107/H107*100,0)/100 -> 0.73 | J107: =IF(I107>=Summary!$L$6,"Eligible","Shortage") -> Shortage | K107: =IF(I107<Summary!$L$8,"YES","No") -> No | L107: =IF(I107>=Summary!$L$7,"Counted","Not Counted") -> Counted | M107: =IF(I107>=Summary!$L$6,20,ROUND(I107/Summary!$L$6*10,1)*2) -> 19.4 | N107: =20-M107 -> 0.6 | O107: =IF(I107>=Summary!$L$6,"75%+ (all benefits)",IF(I107>=Summary!$L$7,"55–74%",IF(I107>=Summary!$L$8,"30–54%","Below 30%"))) -> 55–74%
A108: 103 | B108: 3CS-B | C108: PIET25CS106 | D108: NISHA P | E108: 46300 | F108: 300 | G108: 66 | H108: 366 | I108: =ROUND(F108/H108*100,0)/100 -> 0.82 | J108: =IF(I108>=Summary!$L$6,"Eligible","Shortage") -> Eligible | K108: =IF(I108<Summary!$L$8,"YES","No") -> No | L108: =IF(I108>=Summary!$L$7,"Counted","Not Counted") -> Counted | M108: =IF(I108>=Summary!$L$6,20,ROUND(I108/Summary!$L$6*10,1)*2) -> 20 | N108: =20-M108 -> 0 | O108: =IF(I108>=Summary!$L$6,"75%+ (all benefits)",IF(I108>=Summary!$L$7,"55–74%",IF(I108>=Summary!$L$8,"30–54%","Below 30%"))) -> 75%+ (all benefits)
A109: 104 | B109: 3CS-B | C109: PIET25CS107 | D109: PAHAL JAIN | E109: 46300 | F109: 262 | G109: 104 | H109: 366 | I109: =ROUND(F109/H109*100,0)/100 -> 0.72 | J109: =IF(I109>=Summary!$L$6,"Eligible","Shortage") -> Shortage | K109: =IF(I109<Summary!$L$8,"YES","No") -> No | L109: =IF(I109>=Summary!$L$7,"Counted","Not Counted") -> Counted | M109: =IF(I109>=Summary!$L$6,20,ROUND(I109/Summary!$L$6*10,1)*2) -> 19.2 | N109: =20-M109 -> 0.8 | O109: =IF(I109>=Summary!$L$6,"75%+ (all benefits)",IF(I109>=Summary!$L$7,"55–74%",IF(I109>=Summary!$L$8,"30–54%","Below 30%"))) -> 55–74%
A110: 105 | B110: 3CS-B | C110: PIET25CS108 | D110: PALAK | E110: 46300 | F110: 281 | G110: 85 | H110: 366 | I110: =ROUND(F110/H110*100,0)/100 -> 0.77 | J110: =IF(I110>=Summary!$L$6,"Eligible","Shortage") -> Eligible | K110: =IF(I110<Summary!$L$8,"YES","No") -> No | L110: =IF(I110>=Summary!$L$7,"Counted","Not Counted") -> Counted | M110: =IF(I110>=Summary!$L$6,20,ROUND(I110/Summary!$L$6*10,1)*2) -> 20 | N110: =20-M110 -> 0 | O110: =IF(I110>=Summary!$L$6,"75%+ (all benefits)",IF(I110>=Summary!$L$7,"55–74%",IF(I110>=Summary!$L$8,"30–54%","Below 30%"))) -> 75%+ (all benefits)
A111: 106 | B111: 3CS-B | C111: PIET25CS109 | D111: PARAS ARORA | E111: 46300 | F111: 311 | G111: 55 | H111: 366 | I111: =ROUND(F111/H111*100,0)/100 -> 0.85 | J111: =IF(I111>=Summary!$L$6,"Eligible","Shortage") -> Eligible | K111: =IF(I111<Summary!$L$8,"YES","No") -> No | L111: =IF(I111>=Summary!$L$7,"Counted","Not Counted") -> Counted | M111: =IF(I111>=Summary!$L$6,20,ROUND(I111/Summary!$L$6*10,1)*2) -> 20 | N111: =20-M111 -> 0 | O111: =IF(I111>=Summary!$L$6,"75%+ (all benefits)",IF(I111>=Summary!$L$7,"55–74%",IF(I111>=Summary!$L$8,"30–54%","Below 30%"))) -> 75%+ (all benefits)
A112: 107 | B112: 3CS-B | C112: PIET25CS110 | D112: PARTH PANCHARIYA | E112: 46300 | F112: 293 | G112: 73 | H112: 366 | I112: =ROUND(F112/H112*100,0)/100 -> 0.8 | J112: =IF(I112>=Summary!$L$6,"Eligible","Shortage") -> Eligible | K112: =IF(I112<Summary!$L$8,"YES","No") -> No | L112: =IF(I112>=Summary!$L$7,"Counted","Not Counted") -> Counted | M112: =IF(I112>=Summary!$L$6,20,ROUND(I112/Summary!$L$6*10,1)*2) -> 20 | N112: =20-M112 -> 0 | O112: =IF(I112>=Summary!$L$6,"75%+ (all benefits)",IF(I112>=Summary!$L$7,"55–74%",IF(I112>=Summary!$L$8,"30–54%","Below 30%"))) -> 75%+ (all benefits)
A113: 108 | B113: 3CS-B | C113: PIET25CS111 | D113: PEEHU SHARMA | E113: 46300 | F113: 253 | G113: 113 | H113: 366 | I113: =ROUND(F113/H113*100,0)/100 -> 0.69 | J113: =IF(I113>=Summary!$L$6,"Eligible","Shortage") -> Shortage | K113: =IF(I113<Summary!$L$8,"YES","No") -> No | L113: =IF(I113>=Summary!$L$7,"Counted","Not Counted") -> Counted | M113: =IF(I113>=Summary!$L$6,20,ROUND(I113/Summary!$L$6*10,1)*2) -> 18.4 | N113: =20-M113 -> 1.6 | O113: =IF(I113>=Summary!$L$6,"75%+ (all benefits)",IF(I113>=Summary!$L$7,"55–74%",IF(I113>=Summary!$L$8,"30–54%","Below 30%"))) -> 55–74%
A114: 109 | B114: 3CS-B | C114: PIET25CS112 | D114: PRADEEP SINGH KHANGAROT | E114: 46300 | F114: 298 | G114: 68 | H114: 366 | I114: =ROUND(F114/H114*100,0)/100 -> 0.81 | J114: =IF(I114>=Summary!$L$6,"Eligible","Shortage") -> Eligible | K114: =IF(I114<Summary!$L$8,"YES","No") -> No | L114: =IF(I114>=Summary!$L$7,"Counted","Not Counted") -> Counted | M114: =IF(I114>=Summary!$L$6,20,ROUND(I114/Summary!$L$6*10,1)*2) -> 20 | N114: =20-M114 -> 0 | O114: =IF(I114>=Summary!$L$6,"75%+ (all benefits)",IF(I114>=Summary!$L$7,"55–74%",IF(I114>=Summary!$L$8,"30–54%","Below 30%"))) -> 75%+ (all benefits)
... A129: 124 | B129: 3CS-B | C129: PIET25CS191 | D129: MANISH SHARMA | E129: 46300 | F129: 302 | G129: 64 | H129: 366 | I129: =ROUND(F129/H129*100,0)/100 -> 0.83 | J129: =IF(I129>=Summary!$L$6,"Eligible","Shortage") -> Eligible | K129: =IF(I129<Summary!$L$8,"YES","No") -> No | L129: =IF(I129>=Summary!$L$7,"Counted","Not Counted") -> Counted | M129: =IF(I129>=Summary!$L$6,20,ROUND(I129/Summary!$L$6*10,1)*2) -> 20 | N129: =20-M129 -> 0 | O129: =IF(I129>=Summary!$L$6,"75%+ (all benefits)",IF(I129>=Summary!$L$7,"55–74%",IF(I129>=Summary!$L$8,"30–54%","Below 30%"))) -> 75%+ (all benefits)
A130: 125 | B130: 3CS-B | C130: PIET25CS193 | E130: 46300 | F130: 327 | G130: 39 | H130: 366 | I130: =ROUND(F130/H130*100,0)/100 -> 0.89 | J130: =IF(I130>=Summary!$L$6,"Eligible","Shortage") -> Eligible | K130: =IF(I130<Summary!$L$8,"YES","No") -> No | L130: =IF(I130>=Summary!$L$7,"Counted","Not Counted") -> Counted | M130: =IF(I130>=Summary!$L$6,20,ROUND(I130/Summary!$L$6*10,1)*2) -> 20 | N130: =20-M130 -> 0 | O130: =IF(I130>=Summary!$L$6,"75%+ (all benefits)",IF(I130>=Summary!$L$7,"55–74%",IF(I130>=Summary!$L$8,"30–54%","Below 30%"))) -> 75%+ (all benefits)
A131: 126 | B131: 3CS-C | C131: PIET25CS128 | D131: RAHUL JANGIR | E131: 46300 | F131: 275 | G131: 91 | H131: 366 | I131: =ROUND(F131/H131*100,0)/100 -> 0.75 | J131: =IF(I131>=Summary!$L$6,"Eligible","Shortage") -> Eligible | K131: =IF(I131<Summary!$L$8,"YES","No") -> No | L131: =IF(I131>=Summary!$L$7,"Counted","Not Counted") -> Counted | M131: =IF(I131>=Summary!$L$6,20,ROUND(I131/Summary!$L$6*10,1)*2) -> 20 | N131: =20-M131 -> 0 | O131: =IF(I131>=Summary!$L$6,"75%+ (all benefits)",IF(I131>=Summary!$L$7,"55–74%",IF(I131>=Summary!$L$8,"30–54%","Below 30%"))) -> 75%+ (all benefits)
A132: 127 | B132: 3CS-C | C132: PIET25CS129 | D132: RAHUL SHARMA | E132: 46300 | F132: 286 | G132: 80 | H132: 366 | I132: =ROUND(F132/H132*100,0)/100 -> 0.78 | J132: =IF(I132>=Summary!$L$6,"Eligible","Shortage") -> Eligible | K132: =IF(I132<Summary!$L$8,"YES","No") -> No | L132: =IF(I132>=Summary!$L$7,"Counted","Not Counted") -> Counted | M132: =IF(I132>=Summary!$L$6,20,ROUND(I132/Summary!$L$6*10,1)*2) -> 20 | N132: =20-M132 -> 0 | O132: =IF(I132>=Summary!$L$6,"75%+ (all benefits)",IF(I132>=Summary!$L$7,"55–74%",IF(I132>=Summary!$L$8,"30–54%","Below 30%"))) -> 75%+ (all benefits)
A133: 128 | B133: 3CS-C | C133: PIET25CS130 | D133: RAJEEV KUMAR GOYAL | E133: 46300 | F133: 301 | G133: 65 | H133: 366 | I133: =ROUND(F133/H133*100,0)/100 -> 0.82 | J133: =IF(I133>=Summary!$L$6,"Eligible","Shortage") -> Eligible | K133: =IF(I133<Summary!$L$8,"YES","No") -> No | L133: =IF(I133>=Summary!$L$7,"Counted","Not Counted") -> Counted | M133: =IF(I133>=Summary!$L$6,20,ROUND(I133/Summary!$L$6*10,1)*2) -> 20 | N133: =20-M133 -> 0 | O133: =IF(I133>=Summary!$L$6,"75%+ (all benefits)",IF(I133>=Summary!$L$7,"55–74%",IF(I133>=Summary!$L$8,"30–54%","Below 30%"))) -> 75%+ (all benefits)
A134: 129 | B134: 3CS-C | C134: PIET25CS131 | D134: RAJYAVARDHAN SINGH RATHORE | E134: 46300 | F134: 250 | G134: 116 | H134: 366 | I134: =ROUND(F134/H134*100,0)/100 -> 0.68 | J134: =IF(I134>=Summary!$L$6,"Eligible","Shortage") -> Shortage | K134: =IF(I134<Summary!$L$8,"YES","No") -> No | L134: =IF(I134>=Summary!$L$7,"Counted","Not Counted") -> Counted | M134: =IF(I134>=Summary!$L$6,20,ROUND(I134/Summary!$L$6*10,1)*2) -> 18.2 | N134: =20-M134 -> 1.8 | O134: =IF(I134>=Summary!$L$6,"75%+ (all benefits)",IF(I134>=Summary!$L$7,"55–74%",IF(I134>=Summary!$L$8,"30–54%","Below 30%"))) -> 55–74%
A135: 130 | B135: 3CS-C | C135: PIET25CS132 | D135: RAVIKANT SHARMA | E135: 46300 | F135: 282 | G135: 84 | H135: 366 | I135: =ROUND(F135/H135*100,0)/100 -> 0.77 | J135: =IF(I135>=Summary!$L$6,"Eligible","Shortage") -> Eligible | K135: =IF(I135<Summary!$L$8,"YES","No") -> No | L135: =IF(I135>=Summary!$L$7,"Counted","Not Counted") -> Counted | M135: =IF(I135>=Summary!$L$6,20,ROUND(I135/Summary!$L$6*10,1)*2) -> 20 | N135: =20-M135 -> 0 | O135: =IF(I135>=Summary!$L$6,"75%+ (all benefits)",IF(I135>=Summary!$L$7,"55–74%",IF(I135>=Summary!$L$8,"30–54%","Below 30%"))) -> 75%+ (all benefits)
A136: 131 | B136: 3CS-C | C136: PIET25CS133 | D136: REHAN IKRAM | E136: 46300 | F136: 308 | G136: 58 | H136: 366 | I136: =ROUND(F136/H136*100,0)/100 -> 0.84 | J136: =IF(I136>=Summary!$L$6,"Eligible","Shortage") -> Eligible | K136: =IF(I136<Summary!$L$8,"YES","No") -> No | L136: =IF(I136>=Summary!$L$7,"Counted","Not Counted") -> Counted | M136: =IF(I136>=Summary!$L$6,20,ROUND(I136/Summary!$L$6*10,1)*2) -> 20 | N136: =20-M136 -> 0 | O136: =IF(I136>=Summary!$L$6,"75%+ (all benefits)",IF(I136>=Summary!$L$7,"55–74%",IF(I136>=Summary!$L$8,"30–54%","Below 30%"))) -> 75%+ (all benefits)
A137: 132 | B137: 3CS-C | C137: PIET25CS134 | D137: RIDHIMA DADHICH | E137: 46300 | F137: 196 | G137: 170 | H137: 366 | I137: =ROUND(F137/H137*100,0)/100 -> 0.54 | J137: =IF(I137>=Summary!$L$6,"Eligible","Shortage") -> Shortage | K137: =IF(I137<Summary!$L$8,"YES","No") -> No | L137: =IF(I137>=Summary!$L$7,"Counted","Not Counted") -> Not Counted | M137: =IF(I137>=Summary!$L$6,20,ROUND(I137/Summary!$L$6*10,1)*2) -> 14.4 | N137: =20-M137 -> 5.6 | O137: =IF(I137>=Summary!$L$6,"75%+ (all benefits)",IF(I137>=Summary!$L$7,"55–74%",IF(I137>=Summary!$L$8,"30–54%","Below 30%"))) -> 30–54%
A138: 133 | B138: 3CS-C | C138: PIET25CS135 | D138: RISHABH NANDI | E138: 46300 | F138: 272 | G138: 94 | H138: 366 | I138: =ROUND(F138/H138*100,0)/100 -> 0.74 | J138: =IF(I138>=Summary!$L$6,"Eligible","Shortage") -> Shortage | K138: =IF(I138<Summary!$L$8,"YES","No") -> No | L138: =IF(I138>=Summary!$L$7,"Counted","Not Counted") -> Counted | M138: =IF(I138>=Summary!$L$6,20,ROUND(I138/Summary!$L$6*10,1)*2) -> 19.8 | N138: =20-M138 -> 0.2 | O138: =IF(I138>=Summary!$L$6,"75%+ (all benefits)",IF(I138>=Summary!$L$7,"55–74%",IF(I138>=Summary!$L$8,"30–54%","Below 30%"))) -> 55–74%
...
