Workbook

Sheet Summary
A1: Poornima Institute of Engineering and Technology, Jaipur — Department of Computer Engineering
A2: B.Tech V Semester (CSE & CS(R)) — RTU Debarment, Assignment Eligibility, DECA/SODECA Marks & Scope for Improvement
A3: Prepared by: Dr. Anil Kumar, Professor & Head, Department of Computer Engineering. Source: Digital Campus 'Complete Attendance Details' for Sections 5CS-A, 5CS-B, 5CS-C and 5CSR-D, data synchronised 7 Oct 2026. 'Improvement possible' = position on the Last Teaching Day (13 Nov 2026) if the student attends every remaining class. Student-wise details are on the 'Full Report' tab.
A5: Criteria and assumptions (edit the yellow cells — every figure on both tabs recalculates)
A6: RTU minimum attendance for examination eligibility; also the level for full DECA/SODECA attendance marks (20/20) | L6: 0.75
A7: Assignments are counted only at or above this attendance (Department rule, as instructed by HOD) | L7: 0.55
A8: RTU debarment risk: attendance below this level (threshold used in Department reports, as instructed by HOD) | L8: 0.3
A9: Attendance position as on (Digital Campus data synchronised) | L9: 46302
A10: Last Teaching Day, B.Tech V Semester (PIET Academic Calendar 2026-27) | L10: 46339
A11: Teaching days left, 8 Oct – 13 Nov (Mon–Fri; excl. Maha Navami 19 Oct, Vijayadashami 20 Oct and Diwali break 6 & 9–11 Nov) | L11: 21
A12: Periods per day (calibrated: 361 periods logged over 67 Mon–Fri teaching days since 6 Jul 2026) | L12: 5.39
A13: Estimated periods left till the Last Teaching Day (= teaching days × periods per day, rounded) | L13: =ROUND($L$11*$L$12,0) -> 113
A15: Section-wise position as on 7 October 2026
A16: Section | B16: Students | C16: Average Attendance | D16: 75% & above (RTU eligible) | E16: % of Section | F16: Below 75% (RTU shortage) | G16: RTU Debar Risk (<30%) | H16: Assignments Counted (55%+) | I16: Assignments NOT Counted (<55%) | J16: Average DECA (/20) | K16: Full DECA 20/20 | L16: DECA Marks Lost (Section Total)
A17: 5CS-A | B17: =COUNTIF('Full Report'!$B$6:$B$218,"5CS-A") -> 61 | C17: =AVERAGEIF('Full Report'!$B$6:$B$218,"5CS-A",'Full Report'!$H$6:$H$218) -> 0.61245902 | D17: =COUNTIFS('Full Report'!$B$6:$B$218,"5CS-A",'Full Report'!$H$6:$H$218,">="&Summary!$L$6) -> 20 | E17: =IF(B17=0,"",D17/B17) -> 0.32786885 | F17: =B17-D17 -> 41 | G17: =COUNTIFS('Full Report'!$B$6:$B$218,"5CS-A",'Full Report'!$H$6:$H$218,"<"&Summary!$L$8) -> 9 | H17: =COUNTIFS('Full Report'!$B$6:$B$218,"5CS-A",'Full Report'!$H$6:$H$218,">="&Summary!$L$7) -> 45 | I17: =B17-H17 -> 16 | J17: =AVERAGEIF('Full Report'!$B$6:$B$218,"5CS-A",'Full Report'!$L$6:$L$218) -> 15.872131 | K17: =COUNTIFS('Full Report'!$B$6:$B$218,"5CS-A",'Full Report'!$L$6:$L$218,">=20") -> 20 | L17: =SUMIF('Full Report'!$B$6:$B$218,"5CS-A",'Full Report'!$M$6:$M$218) -> 251.8
A18: 5CS-B | B18: =COUNTIF('Full Report'!$B$6:$B$218,"5CS-B") -> 62 | C18: =AVERAGEIF('Full Report'!$B$6:$B$218,"5CS-B",'Full Report'!$H$6:$H$218) -> 0.62370968 | D18: =COUNTIFS('Full Report'!$B$6:$B$218,"5CS-B",'Full Report'!$H$6:$H$218,">="&Summary!$L$6) -> 12 | E18: =IF(B18=0,"",D18/B18) -> 0.19354839 | F18: =B18-D18 -> 50 | G18: =COUNTIFS('Full Report'!$B$6:$B$218,"5CS-B",'Full Report'!$H$6:$H$218,"<"&Summary!$L$8) -> 1 | H18: =COUNTIFS('Full Report'!$B$6:$B$218,"5CS-B",'Full Report'!$H$6:$H$218,">="&Summary!$L$7) -> 48 | I18: =B18-H18 -> 14 | J18: =AVERAGEIF('Full Report'!$B$6:$B$218,"5CS-B",'Full Report'!$L$6:$L$218) -> 16.503226 | K18: =COUNTIFS('Full Report'!$B$6:$B$218,"5CS-B",'Full Report'!$L$6:$L$218,">=20") -> 12 | L18: =SUMIF('Full Report'!$B$6:$B$218,"5CS-B",'Full Report'!$M$6:$M$218) -> 216.8
A19: 5CS-C | B19: =COUNTIF('Full Report'!$B$6:$B$218,"5CS-C") -> 62 | C19: =AVERAGEIF('Full Report'!$B$6:$B$218,"5CS-C",'Full Report'!$H$6:$H$218) -> 0.57887097 | D19: =COUNTIFS('Full Report'!$B$6:$B$218,"5CS-C",'Full Report'!$H$6:$H$218,">="&Summary!$L$6) -> 26 | E19: =IF(B19=0,"",D19/B19) -> 0.41935484 | F19: =B19-D19 -> 36 | G19: =COUNTIFS('Full Report'!$B$6:$B$218,"5CS-C",'Full Report'!$H$6:$H$218,"<"&Summary!$L$8) -> 13 | H19: =COUNTIFS('Full Report'!$B$6:$B$218,"5CS-C",'Full Report'!$H$6:$H$218,">="&Summary!$L$7) -> 43 | I19: =B19-H19 -> 19 | J19: =AVERAGEIF('Full Report'!$B$6:$B$218,"5CS-C",'Full Report'!$L$6:$L$218) -> 14.964516 | K19: =COUNTIFS('Full Report'!$B$6:$B$218,"5CS-C",'Full Report'!$L$6:$L$218,">=20") -> 26 | L19: =SUMIF('Full Report'!$B$6:$B$218,"5CS-C",'Full Report'!$M$6:$M$218) -> 312.2
A20: 5CSR-D | B20: =COUNTIF('Full Report'!$B$6:$B$218,"5CSR-D") -> 28 | C20: =AVERAGEIF('Full Report'!$B$6:$B$218,"5CSR-D",'Full Report'!$H$6:$H$218) -> 0.59428571 | D20: =COUNTIFS('Full Report'!$B$6:$B$218,"5CSR-D",'Full Report'!$H$6:$H$218,">="&Summary!$L$6) -> 5 | E20: =IF(B20=0,"",D20/B20) -> 0.17857143 | F20: =B20-D20 -> 23 | G20: =COUNTIFS('Full Report'!$B$6:$B$218,"5CSR-D",'Full Report'!$H$6:$H$218,"<"&Summary!$L$8) -> 3 | H20: =COUNTIFS('Full Report'!$B$6:$B$218,"5CSR-D",'Full Report'!$H$6:$H$218,">="&Summary!$L$7) -> 20 | I20: =B20-H20 -> 8 | J20: =AVERAGEIF('Full Report'!$B$6:$B$218,"5CSR-D",'Full Report'!$L$6:$L$218) -> 15.685714 | K20: =COUNTIFS('Full Report'!$B$6:$B$218,"5CSR-D",'Full Report'!$L$6:$L$218,">=20") -> 5 | L20: =SUMIF('Full Report'!$B$6:$B$218,"5CSR-D",'Full Report'!$M$6:$M$218) -> 120.8
A21: Total (V Sem) | B21: =SUM(B17:B20) -> 213 | C21: =AVERAGE('Full Report'!$H$6:$H$218) -> 0.60356808 | D21: =SUM(D17:D20) -> 63 | E21: =IF(B21=0,"",D21/B21) -> 0.29577465 | F21: =SUM(F17:F20) -> 150 | G21: =SUM(G17:G20) -> 26 | H21: =SUM(H17:H20) -> 156 | I21: =SUM(I17:I20) -> 57 | J21: =AVERAGE('Full Report'!$L$6:$L$218) -> 15.767136 | K21: =SUM(K17:K20) -> 63 | L21: =SUM(L17:L20) -> 901.6
A23: Scope for improvement — position on the Last Teaching Day (13 Nov 2026) if every remaining class is attended
A24: Measure | F24: Today (7 Oct) | H24: On 13 Nov (if regular) | J24: Change
A25: Average attendance | F25: =AVERAGE('Full Report'!$H$6:$H$218) -> 0.60356808 | H25: =AVERAGE('Full Report'!$O$6:$O$218) -> 0.69797548 | J25: =H25-F25 -> 0.094407401
A26: Average DECA/SODECA attendance marks (/20) | F26: =AVERAGE('Full Report'!$L$6:$L$218) -> 15.767136 | H26: =AVERAGE('Full Report'!$P$6:$P$218) -> 17.740845 | J26: =H26-F26 -> 1.9737089
A27: Students meeting RTU 75% eligibility | F27: =COUNTIF('Full Report'!$H$6:$H$218,">="&Summary!$L$6) -> 63 | H27: =COUNTIF('Full Report'!$O$6:$O$218,">="&Summary!$L$6) -> 104 | J27: =H27-F27 -> 41
A28: Students whose assignments are counted (55%+) | F28: =COUNTIF('Full Report'!$H$6:$H$218,">="&Summary!$L$7) -> 156 | H28: =COUNTIF('Full Report'!$O$6:$O$218,">="&Summary!$L$7) -> 178 | J28: =H28-F28 -> 22
A29: Students at RTU debarment risk (<30%) | F29: =COUNTIF('Full Report'!$H$6:$H$218,"<"&Summary!$L$8) -> 26 | H29: =COUNTIF('Full Report'!$O$6:$O$218,"<"&Summary!$L$8) -> 10 | J29: =H29-F29 -> -16
A30: Students with full DECA 20/20 | F30: =COUNTIF('Full Report'!$L$6:$L$218,">=20") -> 63 | H30: =COUNTIF('Full Report'!$P$6:$P$218,">=20") -> 106 | J30: =H30-F30 -> 43
A31: Total DECA attendance marks lost today (whole semester) / marks recoverable by 13 Nov | F31: =SUM('Full Report'!$M$6:$M$218) -> 901.6 | H31: =SUM('Full Report'!$P$6:$P$218)-SUM('Full Report'!$L$6:$L$218) -> 420.4 | J31: =SUM('Full Report'!$Q$6:$Q$218) -> 420.4
A33: Students at RTU debarment risk today (attendance below 30%) — immediate action required
A34: S.No | B34: Section | C34: Reg. No | D34: Name | G34: Present | H34: Total | I34: Attendance Today | J34: Max % on 13 Nov | K34: Will Cross 30% by 13 Nov?
A35: 1 | B35: 5CS-A | C35: PIET24CS056 | D35: GOURAV BOHRA | G35: ='Full Report'!E57 -> 2 | H35: ='Full Report'!G57 -> 361 | I35: ='Full Report'!H57 -> 0.01 | J35: ='Full Report'!O57 -> 0.24261603 | K35: =IF('Full Report'!O57>=Summary!$L$8,"Yes","No") -> No
A36: 2 | B36: 5CS-A | C36: PIET25CS800 | D36: TANISH | G36: ='Full Report'!E65 -> 4 | H36: ='Full Report'!G65 -> 361 | I36: ='Full Report'!H65 -> 0.01 | J36: ='Full Report'!O65 -> 0.24683544 | K36: =IF('Full Report'!O65>=Summary!$L$8,"Yes","No") -> No
A37: 3 | B37: 5CS-A | C37: PIET24CS027 | D37: ANUSHKA JADDON | G37: ='Full Report'!E31 -> 25 | H37: ='Full Report'!G31 -> 361 | I37: ='Full Report'!H31 -> 0.07 | J37: ='Full Report'!O31 -> 0.29113924 | K37: =IF('Full Report'!O31>=Summary!$L$8,"Yes","No") -> No
A38: 4 | B38: 5CS-A | C38: PIET24CS051 | D38: FEZAN KHAN | G38: ='Full Report'!E52 -> 65 | H38: ='Full Report'!G52 -> 361 | I38: ='Full Report'!H52 -> 0.18 | J38: ='Full Report'!O52 -> 0.37552743 | K38: =IF('Full Report'!O52>=Summary!$L$8,"Yes","No") -> Yes
A39: 5 | B39: 5CS-A | C39: PIET24CS020 | D39: ANKIT SINGH SHEKHAWAT | G39: ='Full Report'!E25 -> 69 | H39: ='Full Report'!G25 -> 361 | I39: ='Full Report'!H25 -> 0.19 | J39: ='Full Report'!O25 -> 0.38396624 | K39: =IF('Full Report'!O25>=Summary!$L$8,"Yes","No") -> Yes
A40: 6 | B40: 5CS-A | C40: PIET24CS015 | D40: ALOK SHARMA | G40: ='Full Report'!E20 -> 70 | H40: ='Full Report'!G20 -> 361 | I40: ='Full Report'!H20 -> 0.19 | J40: ='Full Report'!O20 -> 0.38607595 | K40: =IF('Full Report'!O20>=Summary!$L$8,"Yes","No") -> Yes
A41: 7 | B41: 5CS-A | C41: PIET24CS042 | D41: DEEPANSHU SHEKHAWAT | G41: ='Full Report'!E44 -> 80 | H41: ='Full Report'!G44 -> 361 | I41: ='Full Report'!H44 -> 0.22 | J41: ='Full Report'!O44 -> 0.407173 | K41: =IF('Full Report'!O44>=Summary!$L$8,"Yes","No") -> Yes
A42: 8 | B42: 5CS-A | C42: PIET24CS045 | D42: DEVESH VIJAY | G42: ='Full Report'!E47 -> 95 | H42: ='Full Report'!G47 -> 361 | I42: ='Full Report'!H47 -> 0.26 | J42: ='Full Report'!O47 -> 0.43881857 | K42: =IF('Full Report'!O47>=Summary!$L$8,"Yes","No") -> Yes
A43: 9 | B43: 5CS-A | C43: PIET24CS062 | D43: HARSHVEER SHEKHAWAT | G43: ='Full Report'!E63 -> 96 | H43: ='Full Report'!G63 -> 361 | I43: ='Full Report'!H63 -> 0.27 | J43: ='Full Report'!O63 -> 0.44092827 | K43: =IF('Full Report'!O63>=Summary!$L$8,"Yes","No") -> Yes
A44: 10 | B44: 5CS-B | C44: PIET24CS109 | D44: NAMAN SHARMA | G44: ='Full Report'!E111 -> 68 | H44: ='Full Report'!G111 -> 361 | I44: ='Full Report'!H111 -> 0.19 | J44: ='Full Report'!O111 -> 0.38185654 | K44: =IF('Full Report'!O111>=Summary!$L$8,"Yes","No") -> Yes
...

Sheet Full Report
A1: Department of Computer Engineering, PIET Jaipur
A2: B.Tech V Semester — Student-wise Status: RTU Eligibility, Assignments, DECA/SODECA Marks and Scope for Improvement
A3: Attendance as on 7 Oct 2026 (Digital Campus), rounded to a whole % as displayed there. DECA/SODECA attendance marks: 20/20 at 75%+, otherwise proportional (attendance ÷ 75% × 10 for Theory and for Practical). '13 Nov' columns assume the student attends every remaining class from 8 Oct. 'Classes to attend' in red = more than the periods left, so that level can no longer be reached. Filter column J = YES for the debar list and column K = Not Counted for the assignments list. Criteria are on the Summary tab.
A5: S.No | B5: Section | C5: Reg. No | D5: Name | E5: Present (7 Oct) | F5: Absent (7 Oct) | G5: Total Periods | H5: Attendance Today | I5: RTU 75% Eligibility | J5: RTU Debar Risk (<30%) | K5: Assignments (55%+) | L5: DECA/SODECA Attendance Marks (/20) | M5: Marks Lost Today | N5: Category Today | O5: Attendance on 13 Nov (if attends every class) | P5: DECA/SODECA on 13 Nov (/20) | Q5: Marks Recoverable | R5: Category on 13 Nov | S5: Classes to Attend for 75% on 13 Nov | T5: Classes to Attend for 55% on 13 Nov | U5: Classes to Attend to Cross 30%
A6: 1 | B6: 5CS-A | C6: PIET24AD011 | D6: ARPIT KUMAR PANCHAL | E6: 298 | F6: 63 | G6: 361 | H6: =ROUND(E6/G6*100,0)/100 -> 0.83 | I6: =IF(H6>=Summary!$L$6,"Eligible","Shortage") -> Eligible | J6: =IF(H6<Summary!$L$8,"YES","No") -> No | K6: =IF(H6>=Summary!$L$7,"Counted","Not Counted") -> Counted | L6: =IF(H6>=Summary!$L$6,20,ROUND(H6/Summary!$L$6*10,1)*2) -> 20 | M6: =20-L6 -> 0 | N6: =IF(H6>=Summary!$L$6,"75%+ (all benefits)",IF(H6>=Summary!$L$7,"55-74%",IF(H6>=Summary!$L$8,"30-54%","Below 30%"))) -> 75%+ (all benefits) | O6: =(E6+Summary!$L$13)/(G6+Summary!$L$13) -> 0.86708861 | P6: =IF(O6>=Summary!$L$6,20,ROUND(O6/Summary!$L$6*10,1)*2) -> 20 | Q6: =P6-L6 -> 0 | R6: =IF(O6>=Summary!$L$6,"75%+ (all benefits)",IF(O6>=Summary!$L$7,"55-74%",IF(O6>=Summary!$L$8,"30-54%","Below 30%"))) -> 75%+ (all benefits) | S6: =MAX(0,ROUNDUP(Summary!$L$6*(G6+Summary!$L$13)-E6,0)) -> 58 | T6: =MAX(0,ROUNDUP(Summary!$L$7*(G6+Summary!$L$13)-E6,0)) -> 0 | U6: =MAX(0,ROUNDUP(Summary!$L$8*(G6+Summary!$L$13)-E6,0)) -> 0
A7: 2 | B7: 5CS-A | C7: PIET24CS001 | D7: AAKRITI GUPTA | E7: 253 | F7: 108 | G7: 361 | H7: =ROUND(E7/G7*100,0)/100 -> 0.7 | I7: =IF(H7>=Summary!$L$6,"Eligible","Shortage") -> Shortage | J7: =IF(H7<Summary!$L$8,"YES","No") -> No | K7: =IF(H7>=Summary!$L$7,"Counted","Not Counted") -> Counted | L7: =IF(H7>=Summary!$L$6,20,ROUND(H7/Summary!$L$6*10,1)*2) -> 18.6 | M7: =20-L7 -> 1.4 | N7: =IF(H7>=Summary!$L$6,"75%+ (all benefits)",IF(H7>=Summary!$L$7,"55-74%",IF(H7>=Summary!$L$8,"30-54%","Below 30%"))) -> 55-74% | O7: =(E7+Summary!$L$13)/(G7+Summary!$L$13) -> 0.7721519 | P7: =IF(O7>=Summary!$L$6,20,ROUND(O7/Summary!$L$6*10,1)*2) -> 20 | Q7: =P7-L7 -> 1.4 | R7: =IF(O7>=Summary!$L$6,"75%+ (all benefits)",IF(O7>=Summary!$L$7,"55-74%",IF(O7>=Summary!$L$8,"30-54%","Below 30%"))) -> 75%+ (all benefits) | S7: =MAX(0,ROUNDUP(Summary!$L$6*(G7+Summary!$L$13)-E7,0)) -> 103 | T7: =MAX(0,ROUNDUP(Summary!$L$7*(G7+Summary!$L$13)-E7,0)) -> 8 | U7: =MAX(0,ROUNDUP(Summary!$L$8*(G7+Summary!$L$13)-E7,0)) -> 0
A8: 3 | B8: 5CS-A | C8: PIET24CS002 | D8: AARYA VIJAY | E8: 285 | F8: 76 | G8: 361 | H8: =ROUND(E8/G8*100,0)/100 -> 0.79 | I8: =IF(H8>=Summary!$L$6,"Eligible","Shortage") -> Eligible | J8: =IF(H8<Summary!$L$8,"YES","No") -> No | K8: =IF(H8>=Summary!$L$7,"Counted","Not Counted") -> Counted | L8: =IF(H8>=Summary!$L$6,20,ROUND(H8/Summary!$L$6*10,1)*2) -> 20 | M8: =20-L8 -> 0 | N8: =IF(H8>=Summary!$L$6,"75%+ (all benefits)",IF(H8>=Summary!$L$7,"55-74%",IF(H8>=Summary!$L$8,"30-54%","Below 30%"))) -> 75%+ (all benefits) | O8: =(E8+Summary!$L$13)/(G8+Summary!$L$13) -> 0.83966245 | P8: =IF(O8>=Summary!$L$6,20,ROUND(O8/Summary!$L$6*10,1)*2) -> 20 | Q8: =P8-L8 -> 0 | R8: =IF(O8>=Summary!$L$6,"75%+ (all benefits)",IF(O8>=Summary!$L$7,"55-74%",IF(O8>=Summary!$L$8,"30-54%","Below 30%"))) -> 75%+ (all benefits) | S8: =MAX(0,ROUNDUP(Summary!$L$6*(G8+Summary!$L$13)-E8,0)) -> 71 | T8: =MAX(0,ROUNDUP(Summary!$L$7*(G8+Summary!$L$13)-E8,0)) -> 0 | U8: =MAX(0,ROUNDUP(Summary!$L$8*(G8+Summary!$L$13)-E8,0)) -> 0
A9: 4 | B9: 5CS-A | C9: PIET24CS003 | D9: AAYUSHMAAN SINGH CHAUHAN | E9: 254 | F9: 107 | G9: 361 | H9: =ROUND(E9/G9*100,0)/100 -> 0.7 | I9: =IF(H9>=Summary!$L$6,"Eligible","Shortage") -> Shortage | J9: =IF(H9<Summary!$L$8,"YES","No") -> No | K9: =IF(H9>=Summary!$L$7,"Counted","Not Counted") -> Counted | L9: =IF(H9>=Summary!$L$6,20,ROUND(H9/Summary!$L$6*10,1)*2) -> 18.6 | M9: =20-L9 -> 1.4 | N9: =IF(H9>=Summary!$L$6,"75%+ (all benefits)",IF(H9>=Summary!$L$7,"55-74%",IF(H9>=Summary!$L$8,"30-54%","Below 30%"))) -> 55-74% | O9: =(E9+Summary!$L$13)/(G9+Summary!$L$13) -> 0.7742616 | P9: =IF(O9>=Summary!$L$6,20,ROUND(O9/Summary!$L$6*10,1)*2) -> 20 | Q9: =P9-L9 -> 1.4 | R9: =IF(O9>=Summary!$L$6,"75%+ (all benefits)",IF(O9>=Summary!$L$7,"55-74%",IF(O9>=Summary!$L$8,"30-54%","Below 30%"))) -> 75%+ (all benefits) | S9: =MAX(0,ROUNDUP(Summary!$L$6*(G9+Summary!$L$13)-E9,0)) -> 102 | T9: =MAX(0,ROUNDUP(Summary!$L$7*(G9+Summary!$L$13)-E9,0)) -> 7 | U9: =MAX(0,ROUNDUP(Summary!$L$8*(G9+Summary!$L$13)-E9,0)) -> 0
A10: 5 | B10: 5CS-A | C10: PIET24CS004 | D10: ABHAY RAJ SINGH | E10: 231 | F10: 130 | G10: 361 | H10: =ROUND(E10/G10*100,0)/100 -> 0.64 | I10: =IF(H10>=Summary!$L$6,"Eligible","Shortage") -> Shortage | J10: =IF(H10<Summary!$L$8,"YES","No") -> No | K10: =IF(H10>=Summary!$L$7,"Counted","Not Counted") -> Counted | L10: =IF(H10>=Summary!$L$6,20,ROUND(H10/Summary!$L$6*10,1)*2) -> 17 | M10: =20-L10 -> 3 | N10: =IF(H10>=Summary!$L$6,"75%+ (all benefits)",IF(H10>=Summary!$L$7,"55-74%",IF(H10>=Summary!$L$8,"30-54%","Below 30%"))) -> 55-74% | O10: =(E10+Summary!$L$13)/(G10+Summary!$L$13) -> 0.7257384 | P10: =IF(O10>=Summary!$L$6,20,ROUND(O10/Summary!$L$6*10,1)*2) -> 19.4 | Q10: =P10-L10 -> 2.4 | R10: =IF(O10>=Summary!$L$6,"75%+ (all benefits)",IF(O10>=Summary!$L$7,"55-74%",IF(O10>=Summary!$L$8,"30-54%","Below 30%"))) -> 55-74% | S10: =MAX(0,ROUNDUP(Summary!$L$6*(G10+Summary!$L$13)-E10,0)) -> 125 | T10: =MAX(0,ROUNDUP(Summary!$L$7*(G10+Summary!$L$13)-E10,0)) -> 30 | U10: =MAX(0,ROUNDUP(Summary!$L$8*(G10+Summary!$L$13)-E10,0)) -> 0
A11: 6 | B11: 5CS-A | C11: PIET24CS005 | D11: ABHINAV CHOUDHARY | E11: 174 | F11: 187 | G11: 361 | H11: =ROUND(E11/G11*100,0)/100 -> 0.48 | I11: =IF(H11>=Summary!$L$6,"Eligible","Shortage") -> Shortage | J11: =IF(H11<Summary!$L$8,"YES","No") -> No | K11: =IF(H11>=Summary!$L$7,"Counted","Not Counted") -> Not Counted | L11: =IF(H11>=Summary!$L$6,20,ROUND(H11/Summary!$L$6*10,1)*2) -> 12.8 | M11: =20-L11 -> 7.2 | N11: =IF(H11>=Summary!$L$6,"75%+ (all benefits)",IF(H11>=Summary!$L$7,"55-74%",IF(H11>=Summary!$L$8,"30-54%","Below 30%"))) -> 30-54% | O11: =(E11+Summary!$L$13)/(G11+Summary!$L$13) -> 0.60548523 | P11: =IF(O11>=Summary!$L$6,20,ROUND(O11/Summary!$L$6*10,1)*2) -> 16.2 | Q11: =P11-L11 -> 3.4 | R11: =IF(O11>=Summary!$L$6,"75%+ (all benefits)",IF(O11>=Summary!$L$7,"55-74%",IF(O11>=Summary!$L$8,"30-54%","Below 30%"))) -> 55-74% | S11: =MAX(0,ROUNDUP(Summary!$L$6*(G11+Summary!$L$13)-E11,0)) -> 182 | T11: =MAX(0,ROUNDUP(Summary!$L$7*(G11+Summary!$L$13)-E11,0)) -> 87 | U11: =MAX(0,ROUNDUP(Summary!$L$8*(G11+Summary!$L$13)-E11,0)) -> 0
A12: 7 | B12: 5CS-A | C12: PIET24CS006 | D12: ABHINAV RAO | E12: 278 | F12: 83 | G12: 361 | H12: =ROUND(E12/G12*100,0)/100 -> 0.77 | I12: =IF(H12>=Summary!$L$6,"Eligible","Shortage") -> Eligible | J12: =IF(H12<Summary!$L$8,"YES","No") -> No | K12: =IF(H12>=Summary!$L$7,"Counted","Not Counted") -> Counted | L12: =IF(H12>=Summary!$L$6,20,ROUND(H12/Summary!$L$6*10,1)*2) -> 20 | M12: =20-L12 -> 0 | N12: =IF(H12>=Summary!$L$6,"75%+ (all benefits)",IF(H12>=Summary!$L$7,"55-74%",IF(H12>=Summary!$L$8,"30-54%","Below 30%"))) -> 75%+ (all benefits) | O12: =(E12+Summary!$L$13)/(G12+Summary!$L$13) -> 0.82489451 | P12: =IF(O12>=Summary!$L$6,20,ROUND(O12/Summary!$L$6*10,1)*2) -> 20 | Q12: =P12-L12 -> 0 | R12: =IF(O12>=Summary!$L$6,"75%+ (all benefits)",IF(O12>=Summary!$L$7,"55-74%",IF(O12>=Summary!$L$8,"30-54%","Below 30%"))) -> 75%+ (all benefits) | S12: =MAX(0,ROUNDUP(Summary!$L$6*(G12+Summary!$L$13)-E12,0)) -> 78 | T12: =MAX(0,ROUNDUP(Summary!$L$7*(G12+Summary!$L$13)-E12,0)) -> 0 | U12: =MAX(0,ROUNDUP(Summary!$L$8*(G12+Summary!$L$13)-E12,0)) -> 0
A13: 8 | B13: 5CS-A | C13: PIET24CS007 | D13: ADAVATIYA DEVANSH | E13: 181 | F13: 180 | G13: 361 | H13: =ROUND(E13/G13*100,0)/100 -> 0.5 | I13: =IF(H13>=Summary!$L$6,"Eligible","Shortage") -> Shortage | J13: =IF(H13<Summary!$L$8,"YES","No") -> No | K13: =IF(H13>=Summary!$L$7,"Counted","Not Counted") -> Not Counted | L13: =IF(H13>=Summary!$L$6,20,ROUND(H13/Summary!$L$6*10,1)*2) -> 13.4 | M13: =20-L13 -> 6.6 | N13: =IF(H13>=Summary!$L$6,"75%+ (all benefits)",IF(H13>=Summary!$L$7,"55-74%",IF(H13>=Summary!$L$8,"30-54%","Below 30%"))) -> 30-54% | O13: =(E13+Summary!$L$13)/(G13+Summary!$L$13) -> 0.62025316 | P13: =IF(O13>=Summary!$L$6,20,ROUND(O13/Summary!$L$6*10,1)*2) -> 16.6 | Q13: =P13-L13 -> 3.2 | R13: =IF(O13>=Summary!$L$6,"75%+ (all benefits)",IF(O13>=Summary!$L$7,"55-74%",IF(O13>=Summary!$L$8,"30-54%","Below 30%"))) -> 55-74% | S13: =MAX(0,ROUNDUP(Summary!$L$6*(G13+Summary!$L$13)-E13,0)) -> 175 | T13: =MAX(0,ROUNDUP(Summary!$L$7*(G13+Summary!$L$13)-E13,0)) -> 80 | U13: =MAX(0,ROUNDUP(Summary!$L$8*(G13+Summary!$L$13)-E13,0)) -> 0
A14: 9 | B14: 5CS-A | C14: PIET24CS008 | D14: ADITYA CHOUDHARY | E14: 259 | F14: 102 | G14: 361 | H14: =ROUND(E14/G14*100,0)/100 -> 0.72 | I14: =IF(H14>=Summary!$L$6,"Eligible","Shortage") -> Shortage | J14: =IF(H14<Summary!$L$8,"YES","No") -> No | K14: =IF(H14>=Summary!$L$7,"Counted","Not Counted") -> Counted | L14: =IF(H14>=Summary!$L$6,20,ROUND(H14/Summary!$L$6*10,1)*2) -> 19.2 | M14: =20-L14 -> 0.8 | N14: =IF(H14>=Summary!$L$6,"75%+ (all benefits)",IF(H14>=Summary!$L$7,"55-74%",IF(H14>=Summary!$L$8,"30-54%","Below 30%"))) -> 55-74% | O14: =(E14+Summary!$L$13)/(G14+Summary!$L$13) -> 0.78481013 | P14: =IF(O14>=Summary!$L$6,20,ROUND(O14/Summary!$L$6*10,1)*2) -> 20 | Q14: =P14-L14 -> 0.8 | R14: =IF(O14>=Summary!$L$6,"75%+ (all benefits)",IF(O14>=Summary!$L$7,"55-74%",IF(O14>=Summary!$L$8,"30-54%","Below 30%"))) -> 75%+ (all benefits) | S14: =MAX(0,ROUNDUP(Summary!$L$6*(G14+Summary!$L$13)-E14,0)) -> 97 | T14: =MAX(0,ROUNDUP(Summary!$L$7*(G14+Summary!$L$13)-E14,0)) -> 2 | U14: =MAX(0,ROUNDUP(Summary!$L$8*(G14+Summary!$L$13)-E14,0)) -> 0
A15: 10 | B15: 5CS-A | C15: PIET24CS009 | D15: ADITYA SHARMA | E15: 217 | F15: 144 | G15: 361 | H15: =ROUND(E15/G15*100,0)/100 -> 0.6 | I15: =IF(H15>=Summary!$L$6,"Eligible","Shortage") -> Shortage | J15: =IF(H15<Summary!$L$8,"YES","No") -> No | K15: =IF(H15>=Summary!$L$7,"Counted","Not Counted") -> Counted | L15: =IF(H15>=Summary!$L$6,20,ROUND(H15/Summary!$L$6*10,1)*2) -> 16 | M15: =20-L15 -> 4 | N15: =IF(H15>=Summary!$L$6,"75%+ (all benefits)",IF(H15>=Summary!$L$7,"55-74%",IF(H15>=Summary!$L$8,"30-54%","Below 30%"))) -> 55-74% | O15: =(E15+Summary!$L$13)/(G15+Summary!$L$13) -> 0.69620253 | P15: =IF(O15>=Summary!$L$6,20,ROUND(O15/Summary!$L$6*10,1)*2) -> 18.6 | Q15: =P15-L15 -> 2.6 | R15: =IF(O15>=Summary!$L$6,"75%+ (all benefits)",IF(O15>=Summary!$L$7,"55-74%",IF(O15>=Summary!$L$8,"30-54%","Below 30%"))) -> 55-74% | S15: =MAX(0,ROUNDUP(Summary!$L$6*(G15+Summary!$L$13)-E15,0)) -> 139 | T15: =MAX(0,ROUNDUP(Summary!$L$7*(G15+Summary!$L$13)-E15,0)) -> 44 | U15: =MAX(0,ROUNDUP(Summary!$L$8*(G15+Summary!$L$13)-E15,0)) -> 0
A16: 11 | B16: 5CS-A | C16: PIET24CS011 | D16: AKHILESH SHARMA | E16: 260 | F16: 101 | G16: 361 | H16: =ROUND(E16/G16*100,0)/100 -> 0.72 | I16: =IF(H16>=Summary!$L$6,"Eligible","Shortage") -> Shortage | J16: =IF(H16<Summary!$L$8,"YES","No") -> No | K16: =IF(H16>=Summary!$L$7,"Counted","Not Counted") -> Counted | L16: =IF(H16>=Summary!$L$6,20,ROUND(H16/Summary!$L$6*10,1)*2) -> 19.2 | M16: =20-L16 -> 0.8 | N16: =IF(H16>=Summary!$L$6,"75%+ (all benefits)",IF(H16>=Summary!$L$7,"55-74%",IF(H16>=Summary!$L$8,"30-54%","Below 30%"))) -> 55-74% | O16: =(E16+Summary!$L$13)/(G16+Summary!$L$13) -> 0.78691983 | P16: =IF(O16>=Summary!$L$6,20,ROUND(O16/Summary!$L$6*10,1)*2) -> 20 | Q16: =P16-L16 -> 0.8 | R16: =IF(O16>=Summary!$L$6,"75%+ (all benefits)",IF(O16>=Summary!$L$7,"55-74%",IF(O16>=Summary!$L$8,"30-54%","Below 30%"))) -> 75%+ (all benefits) | S16: =MAX(0,ROUNDUP(Summary!$L$6*(G16+Summary!$L$13)-E16,0)) -> 96 | T16: =MAX(0,ROUNDUP(Summary!$L$7*(G16+Summary!$L$13)-E16,0)) -> 1 | U16: =MAX(0,ROUNDUP(Summary!$L$8*(G16+Summary!$L$13)-E16,0)) -> 0
A17: 12 | B17: 5CS-A | C17: PIET24CS012 | D17: AKSHAT JAIN | E17: 264 | F17: 97 | G17: 361 | H17: =ROUND(E17/G17*100,0)/100 -> 0.73 | I17: =IF(H17>=Summary!$L$6,"Eligible","Shortage") -> Shortage | J17: =IF(H17<Summary!$L$8,"YES","No") -> No | K17: =IF(H17>=Summary!$L$7,"Counted","Not Counted") -> Counted | L17: =IF(H17>=Summary!$L$6,20,ROUND(H17/Summary!$L$6*10,1)*2) -> 19.4 | M17: =20-L17 -> 0.6 | N17: =IF(H17>=Summary!$L$6,"75%+ (all benefits)",IF(H17>=Summary!$L$7,"55-74%",IF(H17>=Summary!$L$8,"30-54%","Below 30%"))) -> 55-74% | O17: =(E17+Summary!$L$13)/(G17+Summary!$L$13) -> 0.79535865 | P17: =IF(O17>=Summary!$L$6,20,ROUND(O17/Summary!$L$6*10,1)*2) -> 20 | Q17: =P17-L17 -> 0.6 | R17: =IF(O17>=Summary!$L$6,"75%+ (all benefits)",IF(O17>=Summary!$L$7,"55-74%",IF(O17>=Summary!$L$8,"30-54%","Below 30%"))) -> 75%+ (all benefits) | S17: =MAX(0,ROUNDUP(Summary!$L$6*(G17+Summary!$L$13)-E17,0)) -> 92 | T17: =MAX(0,ROUNDUP(Summary!$L$7*(G17+Summary!$L$13)-E17,0)) -> 0 | U17: =MAX(0,ROUNDUP(Summary!$L$8*(G17+Summary!$L$13)-E17,0)) -> 0
... A218: 213 | B218: 5CSR-D | C218: PIET24CR036 | D218: KULDEEP NAGAR | E218: 190 | F218: 171 | G218: 361 | H218: =ROUND(E218/G218*100,0)/100 -> 0.53 | I218: =IF(H218>=Summary!$L$6,"Eligible","Shortage") -> Shortage | J218: =IF(H218<Summary!$L$8,"YES","No") -> No | K218: =IF(H218>=Summary!$L$7,"Counted","Not Counted") -> Not Counted | L218: =IF(H218>=Summary!$L$6,20,ROUND(H218/Summary!$L$6*10,1)*2) -> 14.2 | M218: =20-L218 -> 5.8 | N218: =IF(H218>=Summary!$L$6,"75%+ (all benefits)",IF(H218>=Summary!$L$7,"55-74%",IF(H218>=Summary!$L$8,"30-54%","Below 30%"))) -> 30-54% | O218: =(E218+Summary!$L$13)/(G218+Summary!$L$13) -> 0.63924051 | P218: =IF(O218>=Summary!$L$6,20,ROUND(O218/Summary!$L$6*10,1)*2) -> 17 | Q218: =P218-L218 -> 2.8 | R218: =IF(O218>=Summary!$L$6,"75%+ (all benefits)",IF(O218>=Summary!$L$7,"55-74%",IF(O218>=Summary!$L$8,"30-54%","Below 30%"))) -> 55-74% | S218: =MAX(0,ROUNDUP(Summary!$L$6*(G218+Summary!$L$13)-E218,0)) -> 166 | T218: =MAX(0,ROUNDUP(Summary!$L$7*(G218+Summary!$L$13)-E218,0)) -> 71 | U218: =MAX(0,ROUNDUP(Summary!$L$8*(G218+Summary!$L$13)-E218,0)) -> 0
